Workbook
Name AMAZONAS: Listas!$T$1090:$V$1100
Name ANTIOQUIA: Listas!$T$2:$V$126
Name ARAUCA: Listas!$T$1049:$V$1055
Name ARCHIPIELAGO_DE_SAN_ANDRES: Listas!$T$1088:$V$1089
Name ATLÁNTICO: Listas!$T$127:$V$149
Name BOGOTA: Listas!$T$150:$V$150
Name BOLÍVAR: Listas!$T$151:$V$196
Name BOYACÁ: Listas!$T$197:$V$319
Name CALDAS: Listas!$T$320:$V$346
Name CAQUETÁ: Listas!$T$347:$V$362
Name CASANARE: Listas!$T$1056:$V$1074
Name CAUCA: Listas!$T$363:$V$404
Name CESAR: Listas!$T$405:$V$429
Name CHOCÓ: Listas!$T$576:$V$605
Name CÓRDOBA: Listas!$T$430:$V$459
Name CUNDINAMARCA: Listas!$T$460:$V$575
Name GUAINÍA: Listas!$T$1101:$V$1108
Name GUAVIARE: Listas!$T$1109:$V$1112
Name HUILA: Listas!$T$606:$V$642
Name LA_GUAJIRA: Listas!$T$643:$V$657
Name LST_ACTIVIDAD_ECONOMICA: Listas!#REF!
Name LST_ASIGNATURA: Listas!$E$2:$E$4
Name LST_ESTADO_CONVENIO: Listas!$H$2:$H$12
Name LST_FACULTAD: Listas!$G$2:$G$18
Name LST_MUNICIPIO: Listas!$T$2:$T$1041
Name LST_SECTOR_ECONOMICO: Listas!$J$2:$J$5
Name LST_SEXO: Listas!$K$2:$K$5
Name LST_TEMATICAS: Listas!$D$2:$D$28
Name LST_TIPO_DE_ACTIVIDAD: Listas!$C$2:$C$5
Name LST_TIPO_DE_ACTOR: Listas!$A$2:$A$11
Name LST_TIPO_DE_PROYECTO: Listas!$B$2:$B$6
Name LST_TIPO_ID: Listas!$I$2:$I$7
Name MAGDALENA: Listas!$T$658:$V$687
Name META: Listas!$T$688:$V$716
Name NARIÑO: Listas!$T$717:$V$781
Name NORTE_DE_SANTANDER: Listas!$T$781:$V$820
Name PUTUMAYO: Listas!$T$1075:$V$1087
Name QUINDÍO: Listas!$T$821:$V$832
Name RISARALDA: Listas!$T$833:$V$846
Name SANTANDER: Listas!$T$847:$V$933
Name SUCRE: Listas!$T$934:$V$959
Name TIPOREL: Listas!$L$2:$L$4
Name TOLIMA: Listas!$T$960:$V$1006
Name VALLE_DEL_CAUCA: Listas!$T$1007:$V$1048
Name VAUPÉS: Listas!$T$1113:$V$1118
Name VICHADA: Listas!$T$1119:$V$1122

Sheet INICIO
B2: BASE DE DATOS HISTÓRICA DE PROYECTOS
B3: Hoja de inicio | Mapa de navegación y guía rápida de uso
B5: OBJETIVO DEL ARCHIVO
B6: Centralizar, organizar y dar seguimiento a la información histórica de proyectos, actores, entidades aliadas, indicadores, metas y avances de la facultad.
B8: MAPA DE NAVEGACIÓN
B9: Hoja / módulo | C9: Descripción | D9: Cuándo usarla | E9: Campo clave
B10: Actores | C10: Registra las personas vinculadas a los proyectos y sus datos de identificación, contacto, rol y relación académica. | D10: Agregar o consultar participantes, docentes, estudiantes u otros actores asociados a un proyecto. | E10: numero_documento
B11: Proyectos | C11: Consolida la información principal de cada proyecto: código, semestre, título, tipo, objetivos, temática, fechas, responsable y estado. | D11: Crear, revisar o actualizar la ficha general de cada proyecto. | E11: codigo_proyecto
B12: Entidades | C12: Directorio maestro de organizaciones externas, con NIT o código interno, sector, CIIU, contacto, ubicación y convenio. | D12: Registrar aliados antes de asociarlos a proyectos. | E12: codigo_entidad / NIT
B13: Proyecto_Socios | C13: Relaciona cada proyecto con sus entidades aliadas y define el tipo de vínculo o participación de cada socio. | D13: Vincular uno o varios socios a un proyecto específico. | E13: codigo_proyecto + codigo_entidad
B14: Metas_Indicador | C14: Define las metas asociadas a cada proyecto e indicador, incluyendo periodicidad, tipo de indicador y valor objetivo. | D14: Establecer la línea base y la meta contra la cual se medirá el avance. | E14: codigo_meta
B15: Seguimiento_Indicador | C15: Registra los avances de los indicadores por periodo y calcula el cumplimiento frente a la meta definida. | D15: Actualizar resultados, evidencias de avance y porcentaje de cumplimiento. | E15: codigo_meta + periodo
B16: Bateria_Indicadores | C16: Catálogo maestro de indicadores disponibles para seleccionar familias, subfamilias, descripciones y tipos. | D16: Consultar o ampliar el banco de indicadores disponibles para los proyectos. | E16: codigo_indicador
B17: Listas | C17: Tablas de referencia técnica para alimentar validaciones y listas desplegables del sistema | D17: Mantener opciones de selección como tipos, estados, sectores, municipios y periodicidades. | E17: categorías de validación
B18: TablasODS | C18: Catálogo de ODS, nombres y metas relacionadas para clasificar proyectos e indicadores según la Agenda 2030. | D18: Mapear proyectos e indicadores con Objetivos de Desarrollo Sostenible y metas ODS. | E18: ODS / meta ODS

Sheet Actores
A1: numero_documento | B1: tipo_documento | C1: semestre_periodo | D1: tipo_actor | E1: nombres_apellidos | F1: fecha_nacimiento | G1: sexo | H1: correo_electronico | I1: telefono | J1: direccion | K1: carrera_programa | L1: facultad | M1: asignatura | N1: codigo_proyecto | O1: titulo_proyecto | P1: informe_final(link) | Q1: observaciones
A2: 1013676963 | B2: CC | C2: 2019-10 | D2: Practicante | E2: MARÍA JOSE CASTILLO MORENO | F2: 35733 | G2: F | H2: maria_castillo@javeriana.edu.co | I2: 310/613-5065 | K2: Ingeniería de Sistemas | L2: Ingeniería | M2: PSU | N2: 1910NULOS-2410 | O2: =IFERROR(IF(Tbla_actores[[#This Row],[codigo_proyecto]]="","",_xlfn.XLOOKUP(Tbla_actores[[#This Row],[codigo_proyecto]],Proyectos!$A:$A,Proyectos!$C:$C)),"") -> NULOS
A3: 1032494985 | B3: CC | C3: 2019-10 | D3: Practicante | E3: MIGUEL ÁNGEL GUTIÉRREZ IBAGUE | F3: 35768 | G3: M | H3: miguel_gutierrez@javeriana.edu.co | I3: 310/810-8579 | K3: Ingeniería de Sistemas | L3: Ingeniería | M3: PSU | N3: 1910NULOS-2410 | O3: =IFERROR(IF(Tbla_actores[[#This Row],[codigo_proyecto]]="","",_xlfn.XLOOKUP(Tbla_actores[[#This Row],[codigo_proyecto]],Proyectos!$A:$A,Proyectos!$C:$C)),"") -> NULOS
A4: 1010228428 | B4: CC | C4: 2019-10 | D4: Practicante | E4: DANIELA LÓPEZ BARAHONA | F4: 35247 | G4: F | H4: lo-daniela@javeriana.edu.co | I4: 316/452-6691 | K4: Ingeniería de Sistemas | L4: Ingeniería | M4: PSU | N4: 1910NULOS-2410 | O4: =IFERROR(IF(Tbla_actores[[#This Row],[codigo_proyecto]]="","",_xlfn.XLOOKUP(Tbla_actores[[#This Row],[codigo_proyecto]],Proyectos!$A:$A,Proyectos!$C:$C)),"") -> NULOS
A5: 1032493211 | B5: CC | C5: 2019-10 | D5: Practicante | E5: DAVID ALEJANDRO MOLANO VÁSQUEZ | F5: 35682 | G5: M | H5: david-molano@javeriana.edu.co | I5: 304/587-1500 | K5: Ingeniería de Sistemas | L5: Ingeniería | M5: PSU | N5: 1910NULOS-2410 | O5: =IFERROR(IF(Tbla_actores[[#This Row],[codigo_proyecto]]="","",_xlfn.XLOOKUP(Tbla_actores[[#This Row],[codigo_proyecto]],Proyectos!$A:$A,Proyectos!$C:$C)),"") -> NULOS
A6: 1018502251 | B6: CC | C6: 2019-10 | D6: Practicante | E6: Murillo Castillo,Johan Sebastian | F6: 35799 | G6: M | H6: johanmurillo@javeriana.edu.co | I6: 305/791-8469 | K6: Ingeniería de Sistemas | L6: Ingeniería | M6: PSU | N6: 1910NULOS-2410 | O6: =IFERROR(IF(Tbla_actores[[#This Row],[codigo_proyecto]]="","",_xlfn.XLOOKUP(Tbla_actores[[#This Row],[codigo_proyecto]],Proyectos!$A:$A,Proyectos!$C:$C)),"") -> NULOS
A7: 1032477898 | B7: CC | C7: 2019-10 | D7: Practicante | E7: KANEKO BOJACA,RIE | F7: 35019 | G7: F | H7: rkaneko@javeriana.edu.co | I7: 321/356-0042 | K7: Ingeniería de Sistemas | L7: Ingeniería | M7: PSU | N7: 1910NULOS-2410 | O7: =IFERROR(IF(Tbla_actores[[#This Row],[codigo_proyecto]]="","",_xlfn.XLOOKUP(Tbla_actores[[#This Row],[codigo_proyecto]],Proyectos!$A:$A,Proyectos!$C:$C)),"") -> NULOS
A8: 1016103807 | B8: CC | C8: 2019-10 | D8: Practicante | E8: SANDOVAL ACOSTA,IVAN DARIO | F8: 35924 | G8: M | H8: sandoval.i@javeriana.edu.co | I8: 310/372-0631 | K8: Ingeniería de Sistemas | L8: Ingeniería | M8: PSU | N8: 1910NULOS-2410 | O8: =IFERROR(IF(Tbla_actores[[#This Row],[codigo_proyecto]]="","",_xlfn.XLOOKUP(Tbla_actores[[#This Row],[codigo_proyecto]],Proyectos!$A:$A,Proyectos!$C:$C)),"") -> NULOS
A9: 1014289963 | B9: CC | C9: 2019-10 | D9: Practicante | E9: MARIÑO GUERRA,ANDRES FELIPE | F9: 35621 | G9: M | H9: marinoandres@javeriana.edu.co | I9: 301/632-5339 | K9: Ingeniería de Sistemas | L9: Ingeniería | M9: PSU | N9: 1910NULOS-2410 | O9: =IFERROR(IF(Tbla_actores[[#This Row],[codigo_proyecto]]="","",_xlfn.XLOOKUP(Tbla_actores[[#This Row],[codigo_proyecto]],Proyectos!$A:$A,Proyectos!$C:$C)),"") -> NULOS
A10: 1013680915 | B10: CC | C10: 2019-10 | D10: Practicante | E10: Torres Rodríguez,Oscar Daniel | F10: 36042 | G10: M | H10: oscar_torres@javeriana.edu.co | I10: 320/553-6492 | K10: Ingeniería de Sistemas | L10: Ingeniería | M10: PSU | N10: 1910NULOS-2410 | O10: =IFERROR(IF(Tbla_actores[[#This Row],[codigo_proyecto]]="","",_xlfn.XLOOKUP(Tbla_actores[[#This Row],[codigo_proyecto]],Proyectos!$A:$A,Proyectos!$C:$C)),"") -> NULOS
A11: 1014285017 | B11: CC | C11: 2019-10 | D11: Practicante | E11: AMANDA CAROLINA SOTO VALENCIA | F11: 35448 | G11: F | H11: amandasoto@javeriana.edu.co | I11: 316/696-5901 | K11: Ingeniería de Sistemas | L11: Ingeniería | M11: PSU | N11: 1910NULOS-2410 | O11: =IFERROR(IF(Tbla_actores[[#This Row],[codigo_proyecto]]="","",_xlfn.XLOOKUP(Tbla_actores[[#This Row],[codigo_proyecto]],Proyectos!$A:$A,Proyectos!$C:$C)),"") -> NULOS
A12: 1018513462 | B12: CC | C12: 2019-10 | D12: Practicante | E12: JUAN SEBASTIÁN GONZÁLEZ MORENO | F12: 36431 | G12: M | H12: gonzalezju@javeriana.edu.co | I12: 747-3508 | K12: Ingeniería de Sistemas | L12: Ingeniería | M12: PSU | N12: 1910NULOS-2410 | O12: =IFERROR(IF(Tbla_actores[[#This Row],[codigo_proyecto]]="","",_xlfn.XLOOKUP(Tbla_actores[[#This Row],[codigo_proyecto]],Proyectos!$A:$A,Proyectos!$C:$C)),"") -> NULOS
A13: 1018497844 | B13: CC | C13: 2019-10 | D13: Practicante | E13: JUAN DAVID GAMA PEÑA | F13: 35705 | G13: M | H13: gamaj@javeriana.edu.co | I13: 312/330-2066 | K13: Ingeniería de Sistemas | L13: Ingeniería | M13: PSU | N13: 1910NULOS-2410 | O13: =IFERROR(IF(Tbla_actores[[#This Row],[codigo_proyecto]]="","",_xlfn.XLOOKUP(Tbla_actores[[#This Row],[codigo_proyecto]],Proyectos!$A:$A,Proyectos!$C:$C)),"") -> NULOS
... A453: 1010237594 | B453: CC | C453: 2019-30 | D453: Practicante | E453: RIVERA ARIZA,DANIEL FELIPE | F453: 35816 | G453: M | H453: daniel-rivera@javeriana.edu.co | I453: 322/390-3190 | K453: Ingeniería Civil | L453: Ingeniería | M453: PSU | N453: 1910NULOS-2410 | O453: =IFERROR(IF(Tbla_actores[[#This Row],[codigo_proyecto]]="","",_xlfn.XLOOKUP(Tbla_actores[[#This Row],[codigo_proyecto]],Proyectos!$A:$A,Proyectos!$C:$C)),"") -> NULOS
A454: 1026594289 | B454: CC | C454: 2020-10 | D454: Practicante | E454: Diego Mateus | F454: NO ENCONTRADO | G454: NO ENCONTRADO | H454: NO ENCONTRADO | I454: NO ENCONTRADO | K454: Ingeniería de Sistemas | L454: Ingeniería | M454: NO ENCONTRADO | N454: 1910NULOS-2410 | O454: =IFERROR(IF(Tbla_actores[[#This Row],[codigo_proyecto]]="","",_xlfn.XLOOKUP(Tbla_actores[[#This Row],[codigo_proyecto]],Proyectos!$A:$A,Proyectos!$C:$C)),"") -> NULOS
A455: 1020810281 | B455: CC | C455: 2020-10 | D455: Practicante | E455: ARCINIEGAS BASTIDAS,RODOLFO ALEJANDRO | F455: 34999 | G455: M | H455: rarciniegas@javeriana.edu.co | I455: 319/524-3098 | K455: Ingeniería de Sistemas | L455: Ingeniería | M455: PSU | N455: 1910NULOS-2410 | O455: =IFERROR(IF(Tbla_actores[[#This Row],[codigo_proyecto]]="","",_xlfn.XLOOKUP(Tbla_actores[[#This Row],[codigo_proyecto]],Proyectos!$A:$A,Proyectos!$C:$C)),"") -> NULOS
A456: 1072715070 | B456: CC | C456: 2020-10 | D456: Practicante | E456: HAMILTON SMITH SANTA CRUZ,DANIEL | F456: 35699 | G456: M | H456: d_hamiltonsmith@javeriana.edu.co | I456: 318/644-8414 | K456: Ingeniería de Sistemas | L456: Ingeniería | M456: PSU | N456: 1910NULOS-2410 | O456: =IFERROR(IF(Tbla_actores[[#This Row],[codigo_proyecto]]="","",_xlfn.XLOOKUP(Tbla_actores[[#This Row],[codigo_proyecto]],Proyectos!$A:$A,Proyectos!$C:$C)),"") -> NULOS
A457: 1116448237 | B457: CC | C457: 2020-10 | D457: Practicante | E457: CHAVEZ ALCALDE,SANDRA ISABEL | F457: 35960 | G457: F | H457: sandra.chavez@javeriana.edu.co | I457: 310/837-8039 | K457: Ingeniería de Sistemas | L457: Ingeniería | M457: PSU | N457: 1910NULOS-2410 | O457: =IFERROR(IF(Tbla_actores[[#This Row],[codigo_proyecto]]="","",_xlfn.XLOOKUP(Tbla_actores[[#This Row],[codigo_proyecto]],Proyectos!$A:$A,Proyectos!$C:$C)),"") -> NULOS
A458: 1018484838 | B458: CC | C458: 2020-10 | D458: Practicante | E458: Juan Linares | F458: 35170 | G458: M | H458: linares.juan@javeriana.edu.co | I458: 300/620-9099 | K458: Ingeniería de Sistemas | L458: Ingeniería | M458: PSU | N458: 1910NULOS-2410 | O458: =IFERROR(IF(Tbla_actores[[#This Row],[codigo_proyecto]]="","",_xlfn.XLOOKUP(Tbla_actores[[#This Row],[codigo_proyecto]],Proyectos!$A:$A,Proyectos!$C:$C)),"") -> NULOS
A459: 1019142697 | B459: CC | C459: 2020-10 | D459: Practicante | E459: William Baquero | F459: 35914 | G459: M | H459: w.baquero@javeriana.edu.co | I459: 320/489-7354 | K459: Ingeniería de Sistemas | L459: Ingeniería | M459: PSU | N459: 1910NULOS-2410 | O459: =IFERROR(IF(Tbla_actores[[#This Row],[codigo_proyecto]]="","",_xlfn.XLOOKUP(Tbla_actores[[#This Row],[codigo_proyecto]],Proyectos!$A:$A,Proyectos!$C:$C)),"") -> NULOS
A460: 1030682895 | B460: CC | C460: 2020-10 | D460: Practicante | E460: Juan Castañeda | F460: 35733 | G460: M | H460: castaneda_j@javeriana.edu.co | I460: 301/675-6383 | K460: Ingeniería de Sistemas | L460: Ingeniería | M460: PSU | N460: 1910NULOS-2410 | O460: =IFERROR(IF(Tbla_actores[[#This Row],[codigo_proyecto]]="","",_xlfn.XLOOKUP(Tbla_actores[[#This Row],[codigo_proyecto]],Proyectos!$A:$A,Proyectos!$C:$C)),"") -> NULOS
A461: 1098815582 | B461: CC | C461: 2020-10 | D461: Practicante | E461: Mara Garcés | F461: 36181 | G461: F | H461: maria_garces@javeriana.edu.co | I461: 317/428-4320 | K461: Ingeniería de Sistemas | L461: Ingeniería | M461: PSU | N461: 1910NULOS-2410 | O461: =IFERROR(IF(Tbla_actores[[#This Row],[codigo_proyecto]]="","",_xlfn.XLOOKUP(Tbla_actores[[#This Row],[codigo_proyecto]],Proyectos!$A:$A,Proyectos!$C:$C)),"") -> NULOS
A462: 1032498978 | B462: CC | C462: 2020-10 | D462: Practicante | E462: Juan Leon | F462: 35989 | G462: M | H462: juleon@javeriana.edu.co | I462: 320/409-4111 | K462: Ingeniería de Sistemas | L462: Ingeniería | M462: PSU | N462: 1910NULOS-2410 | O462: =IFERROR(IF(Tbla_actores[[#This Row],[codigo_proyecto]]="","",_xlfn.XLOOKUP(Tbla_actores[[#This Row],[codigo_proyecto]],Proyectos!$A:$A,Proyectos!$C:$C)),"") -> NULOS
A463: 1001171919 | B463: CC | C463: 2020-10 | D463: Practicante | E463: Briam Agudelo | F463: 35986 | G463: M | H463: briam-agudelo@javeriana.edu.co | I463: 365-0289 | K463: Ingeniería de Sistemas | L463: Ingeniería | M463: PSU | N463: 1910NULOS-2410 | O463: =IFERROR(IF(Tbla_actores[[#This Row],[codigo_proyecto]]="","",_xlfn.XLOOKUP(Tbla_actores[[#This Row],[codigo_proyecto]],Proyectos!$A:$A,Proyectos!$C:$C)),"") -> NULOS
A464: 1033815546 | B464: CC | C464: 2020-10 | D464: Practicante | E464: Diego Barajas | F464: 36271 | G464: M | H464: barajas-d@javeriana.edu.co | I464: 320/288-3351 | K464: Ingeniería de Sistemas | L464: Ingeniería | M464: PSU | N464: 1910NULOS-2410 | O464: =IFERROR(IF(Tbla_actores[[#This Row],[codigo_proyecto]]="","",_xlfn.XLOOKUP(Tbla_actores[[#This Row],[codigo_proyecto]],Proyectos!$A:$A,Proyectos!$C:$C)),"") -> NULOS
A465: 1010065358 | B465: CC | C465: 2020-10 | D465: Practicante | E465: Sergio Posada | F465: 36312 | G465: M | H465: sergio_posada@javeriana.edu.co | I465: 320/941-0506 | K465: Ingeniería de Sistemas | L465: Ingeniería | M465: PSU | N465: 1910NULOS-2410 | O465: =IFERROR(IF(Tbla_actores[[#This Row],[codigo_proyecto]]="","",_xlfn.XLOOKUP(Tbla_actores[[#This Row],[codigo_proyecto]],Proyectos!$A:$A,Proyectos!$C:$C)),"") -> NULOS
A466: 1019147850 | B466: CC | C466: 2020-10 | D466: Practicante | E466: CERVANTES PINEDA,NICOLAS ANDRES | F466: 36256 | G466: M | H466: nicolas.cervantes@javeriana.edu.co | I466: 314/298-9463 | K466: Ingeniería de Sistemas | L466: Ingeniería | M466: PSU | N466: 1910NULOS-2410 | O466: =IFERROR(IF(Tbla_actores[[#This Row],[codigo_proyecto]]="","",_xlfn.XLOOKUP(Tbla_actores[[#This Row],[codigo_proyecto]],Proyectos!$A:$A,Proyectos!$C:$C)),"") -> NULOS
... A469: 1023970683 | B469: CC | C469: 2020-10 | D469: Practicante | E469: CRUZ LOPEZ,BRANDONN ANDRES | F469: 36006 | G469: M | H469: brandonn_cruz@javeriana.edu.co | I469: 314/385-7656 | K469: Ingeniería de Sistemas | L469: Ingeniería | M469: PSU | N469: 1910NULOS-2410 | O469: =IFERROR(IF(Tbla_actores[[#This Row],[codigo_proyecto]]="","",_xlfn.XLOOKUP(Tbla_actores[[#This Row],[codigo_proyecto]],Proyectos!$A:$A,Proyectos!$C:$C)),"") -> NULOS
A470: 1006956287 | B470: CC | C470: 2020-10 | D470: Practicante | E470: Kevin Pelaez | F470: NO ENCONTRADO | G470: NO ENCONTRADO | H470: NO ENCONTRADO | I470: NO ENCONTRADO | K470: Ingeniería de Sistemas | L470: Ingeniería | M470: NO ENCONTRADO | N470: 1910NULOS-2410 | O470: =IFERROR(IF(Tbla_actores[[#This Row],[codigo_proyecto]]="","",_xlfn.XLOOKUP(Tbla_actores[[#This Row],[codigo_proyecto]],Proyectos!$A:$A,Proyectos!$C:$C)),"") -> NULOS
A471: 1013684063 | B471: CC | C471: 2020-10 | D471: Practicante | E471: Jonathan Molina | F471: 36055 | G471: M | H471: molina_jonathan@javeriana.edu.co | I471: 319/257-4131 | K471: Ingeniería de Sistemas | L471: Ingeniería | M471: PSU | N471: 1910NULOS-2410 | O471: =IFERROR(IF(Tbla_actores[[#This Row],[codigo_proyecto]]="","",_xlfn.XLOOKUP(Tbla_actores[[#This Row],[codigo_proyecto]],Proyectos!$A:$A,Proyectos!$C:$C)),"") -> NULOS
A472: 1000061573 | B472: CC | C472: 2020-10 | D472: Practicante | E472: Karol Yate | F472: 36776 | G472: F | H472: yatek@javeriana.edu.co | I472: 301/366-0141 | K472: Ingeniería de Sistemas | L472: Ingeniería | M472: PSU | N472: 1910NULOS-2410 | O472: =IFERROR(IF(Tbla_actores[[#This Row],[codigo_proyecto]]="","",_xlfn.XLOOKUP(Tbla_actores[[#This Row],[codigo_proyecto]],Proyectos!$A:$A,Proyectos!$C:$C)),"") -> NULOS
A473: 1018482319 | B473: CC | C473: 2020-10 | D473: Practicante | E473: MAYORGA CORTES,ALEJANDRO | F473: 35086 | G473: M | H473: alejandromayorga@javeriana.edu.co | I473: 321/336-6403 | K473: Ingeniería Electrónica | L473: Ingeniería | M473: PSU | N473: 1910NULOS-2410 | O473: =IFERROR(IF(Tbla_actores[[#This Row],[codigo_proyecto]]="","",_xlfn.XLOOKUP(Tbla_actores[[#This Row],[codigo_proyecto]],Proyectos!$A:$A,Proyectos!$C:$C)),"") -> NULOS
A474: 1020832382 | B474: CC | C474: 2020-10 | D474: Practicante | E474: GARCIA MORALES,BRAYAN RICARDO | F474: 35882 | G474: M | H474: brayan-garcia@javeriana.edu.co | I474: 305/705-3548 | K474: Ingeniería de Sistemas | L474: Ingeniería | M474: PSU | N474: 1910NULOS-2410 | O474: =IFERROR(IF(Tbla_actores[[#This Row],[codigo_proyecto]]="","",_xlfn.XLOOKUP(Tbla_actores[[#This Row],[codigo_proyecto]],Proyectos!$A:$A,Proyectos!$C:$C)),"") -> NULOS
A475: 1098808861 | B475: CC | C475: 2020-10 | D475: Practicante | E475: VERA QUINTERO,LEYDER FABIAN | F475: 35968 | G475: M | H475: vera_l@javeriana.edu.co | I475: 318/618-1915 | K475: Ingeniería de Sistemas | L475: Ingeniería | M475: PSU | N475: 1910NULOS-2410 | O475: =IFERROR(IF(Tbla_actores[[#This Row],[codigo_proyecto]]="","",_xlfn.XLOOKUP(Tbla_actores[[#This Row],[codigo_proyecto]],Proyectos!$A:$A,Proyectos!$C:$C)),"") -> NULOS
A476: 1020811084 | B476: CC | C476: 2020-10 | D476: Practicante | E476: FERNANDEZ ULLOA,DANIEL | F476: 35030 | G476: M | H476: fernandezdaniel@javeriana.edu.co | I476: 310/310-6722 | K476: Ingeniería de Sistemas | L476: Ingeniería | M476: PSU | N476: 1910NULOS-2410 | O476: =IFERROR(IF(Tbla_actores[[#This Row],[codigo_proyecto]]="","",_xlfn.XLOOKUP(Tbla_actores[[#This Row],[codigo_proyecto]],Proyectos!$A:$A,Proyectos!$C:$C)),"") -> NULOS
A477: 1018510763 | B477: CC | C477: 2020-10 | D477: Practicante | E477: PULIDO AVILA,PABLO ALEJANDRO | F477: 36284 | G477: M | H477: pablo.pulido@javeriana.edu.co | I477: 316/690-5604 | K477: Ingeniería de Sistemas | L477: Ingeniería | M477: PSU | N477: 1910NULOS-2410 | O477: =IFERROR(IF(Tbla_actores[[#This Row],[codigo_proyecto]]="","",_xlfn.XLOOKUP(Tbla_actores[[#This Row],[codigo_proyecto]],Proyectos!$A:$A,Proyectos!$C:$C)),"") -> NULOS
A478: 1019143905 | B478: CC | C478: 2020-10 | D478: Practicante | E478: VILLATE OBANDO,NATALIA | F478: 36073 | G478: F | H478: n-villate@javeriana.edu.co | I478: 315/348-8503 | K478: Ingeniería de Sistemas | L478: Ingeniería | M478: PSU | N478: 1910NULOS-2410 | O478: =IFERROR(IF(Tbla_actores[[#This Row],[codigo_proyecto]]="","",_xlfn.XLOOKUP(Tbla_actores[[#This Row],[codigo_proyecto]],Proyectos!$A:$A,Proyectos!$C:$C)),"") -> NULOS
A479: 1019142423 | B479: CC | C479: 2020-10 | D479: Practicante | E479: HARRY ANDRES AVILA ECHEVERRIA | F479: 36032 | G479: M | H479: harryavila@javeriana.edu.co | I479: 321/456-8565 | K479: Ingeniería Industrial | L479: Ingeniería | M479: CDIO-3 | N479: 1910NULOS-2410 | O479: =IFERROR(IF(Tbla_actores[[#This Row],[codigo_proyecto]]="","",_xlfn.XLOOKUP(Tbla_actores[[#This Row],[codigo_proyecto]],Proyectos!$A:$A,Proyectos!$C:$C)),"") -> NULOS
A480: 1023082150 | B480: CC | C480: 2020-10 | D480: Practicante | E480: MARIA CAMILA CAÑON VARGAS | F480: 36043 | G480: F | H480: canonmaria@javeriana.edu.co | I480: 320/856-7504 | K480: Ingeniería Industrial | L480: Ingeniería | M480: CDIO-3 | N480: 1910NULOS-2410 | O480: =IFERROR(IF(Tbla_actores[[#This Row],[codigo_proyecto]]="","",_xlfn.XLOOKUP(Tbla_actores[[#This Row],[codigo_proyecto]],Proyectos!$A:$A,Proyectos!$C:$C)),"") -> NULOS
A481: 1072714201 | B481: CC | C481: 2020-10 | D481: Practicante | E481: JORGE ALBERTO GÓMEZ VIGOYA | F481: 35562 | G481: M | H481: jo.gomez@javeriana.edu.co | I481: 885-9323 | K481: Ingeniería Industrial | L481: Ingeniería | M481: CDIO-3 | N481: 1910NULOS-2410 | O481: =IFERROR(IF(Tbla_actores[[#This Row],[codigo_proyecto]]="","",_xlfn.XLOOKUP(Tbla_actores[[#This Row],[codigo_proyecto]],Proyectos!$A:$A,Proyectos!$C:$C)),"") -> NULOS
...

Sheet Proyectos
A1: codigo_proyecto | B1: semestre | C1: titulo_proyecto | D1: tipo_proyecto | E1: objetivos | F1: tematica | G1: tipo_actividades | H1: encargado_docente | I1: fecha_inicio | J1: fecha_fin | K1: duracion_meses | L1: departamento | M1: municipio | N1: latitud | O1: longitud | P1: estado | Q1: observaciones
A2: 2510ISISTALI-1 | B2: =LEFT(Tbla_proyectos[[#This Row],[codigo_proyecto]],4) -> 2510 | C2: Proyecto 1 | D2: Prácticas | E2: Desarrollo y mantenimiento de la página web de la entidad. Implementación y gestión de estrategias de marketing digital. Configuración y optimización de aplicaciones en Google App. Soporte y administración de la plataforma Salesforce. | F2: Desarrollo Web | G2: Asesoría Técnica | H2: Alicia Mercedes Arenas Valderrama | K2: =IF(OR(Tbla_proyectos[[#This Row],[fecha_inicio]]="",Tbla_proyectos[[#This Row],[fecha_fin]]=""),"",DATEDIF(Tbla_proyectos[[#This Row],[fecha_inicio]],Tbla_proyectos[[#This Row],[fecha_fin]],"M")) | L2: BOGOTA | M2: BOGOTÁ, D.C. | N2: =IF(Tbla_proyectos[[#This Row],[municipio]]="","",VLOOKUP(Tbla_proyectos[[#This Row],[municipio]],INDIRECT(Tbla_proyectos[[#This Row],[departamento]]),2,0)) -> 4.3161077 | O2: =IF(Tbla_proyectos[[#This Row],[municipio]]="","",VLOOKUP(Tbla_proyectos[[#This Row],[municipio]],INDIRECT(Tbla_proyectos[[#This Row],[departamento]]),2,0)) -> 4.3161077
A3: 2530IINDSMAR-2 | B3: =LEFT(Tbla_proyectos[[#This Row],[codigo_proyecto]],4) -> 2530 | C3: Diseño de procesos y procedimientos | D3: Prácticas | E3: Elaborar, documentar y proponer los procesos y procedimientos del colegio Agudelo Restrepo | F3: Gestión de Procesos | G3: Asesoría Técnica y Capacitación | H3: Marcela Camargo Pabón | K3: =IF(OR(Tbla_proyectos[[#This Row],[fecha_inicio]]="",Tbla_proyectos[[#This Row],[fecha_fin]]=""),"",DATEDIF(Tbla_proyectos[[#This Row],[fecha_inicio]],Tbla_proyectos[[#This Row],[fecha_fin]],"M")) | L3: BOGOTA | M3: BOGOTÁ, D.C. | N3: =IF(Tbla_proyectos[[#This Row],[municipio]]="","",VLOOKUP(Tbla_proyectos[[#This Row],[municipio]],INDIRECT(Tbla_proyectos[[#This Row],[departamento]]),2,0)) -> 4.3161077 | O3: =IF(Tbla_proyectos[[#This Row],[municipio]]="","",VLOOKUP(Tbla_proyectos[[#This Row],[municipio]],INDIRECT(Tbla_proyectos[[#This Row],[departamento]]),2,0)) -> 4.3161077 | P3: Nuevo
A4: 2530IINDSMAR-1 | B4: =LEFT(Tbla_proyectos[[#This Row],[codigo_proyecto]],4) -> 2530 | C4: Evaluación de residuos en la playa de Santa Marta | D4: Prácticas | E4: Investigación de microplásticos y manejo de residuos en la playa de Santa Marta Colombia | F4: Gestión de Residuos | G4: Asesoría Técnica y Capacitación | H4: Marcela Camargo Pabón | K4: =IF(OR(Tbla_proyectos[[#This Row],[fecha_inicio]]="",Tbla_proyectos[[#This Row],[fecha_fin]]=""),"",DATEDIF(Tbla_proyectos[[#This Row],[fecha_inicio]],Tbla_proyectos[[#This Row],[fecha_fin]],"M")) | L4: BOGOTA | M4: BOGOTÁ, D.C. | N4: =IF(Tbla_proyectos[[#This Row],[municipio]]="","",VLOOKUP(Tbla_proyectos[[#This Row],[municipio]],INDIRECT(Tbla_proyectos[[#This Row],[departamento]]),2,0)) -> 4.3161077 | O4: =IF(Tbla_proyectos[[#This Row],[municipio]]="","",VLOOKUP(Tbla_proyectos[[#This Row],[municipio]],INDIRECT(Tbla_proyectos[[#This Row],[departamento]]),2,0)) -> 4.3161077 | P4: Nuevo
A5: 2430IINDSMAR-1 | B5: =LEFT(Tbla_proyectos[[#This Row],[codigo_proyecto]],4) -> 2430 | C5: Revisión y ajuste de procesos proyecto estudiar para construir | D5: Prácticas | E5: Revisión y ajuste de procesos del proyecto "Estudiar para Construir". Visitas a sedes a obras de construcción en Fontibón y Madrid para realizar un análisis detallado de los procesos en campo. | F5: Capacitación en Construcción | G5: Asesoría Técnica | H5: Marcela Camargo Pabón | K5: =IF(OR(Tbla_proyectos[[#This Row],[fecha_inicio]]="",Tbla_proyectos[[#This Row],[fecha_fin]]=""),"",DATEDIF(Tbla_proyectos[[#This Row],[fecha_inicio]],Tbla_proyectos[[#This Row],[fecha_fin]],"M")) | L5: BOGOTA | M5: BOGOTÁ, D.C. | N5: =IF(Tbla_proyectos[[#This Row],[municipio]]="","",VLOOKUP(Tbla_proyectos[[#This Row],[municipio]],INDIRECT(Tbla_proyectos[[#This Row],[departamento]]),2,0)) -> 4.3161077 | O5: =IF(Tbla_proyectos[[#This Row],[municipio]]="","",VLOOKUP(Tbla_proyectos[[#This Row],[municipio]],INDIRECT(Tbla_proyectos[[#This Row],[departamento]]),2,0)) -> 4.3161077 | P5: Continuidad
A6: 2510IINDSGIO-5 | B6: =LEFT(Tbla_proyectos[[#This Row],[codigo_proyecto]],4) -> 2510 | C6: PROPUESTA DE GESTION Y ANALISIS ESTRATEGICO | D6: Prácticas | E6: Asesoría técnica por medio de reuniones de exploración, entendimiento, evaluación y ejecución de propuestas de proyectos de ingeniería que le ayuden a la entidad a mejorar la gestión de procesos. | F6: Gestión de Procesos | G6: Asesoría Técnica y Capacitación | H6: Giovanna Rosa Fiorillo Obando | K6: =IF(OR(Tbla_proyectos[[#This Row],[fecha_inicio]]="",Tbla_proyectos[[#This Row],[fecha_fin]]=""),"",DATEDIF(Tbla_proyectos[[#This Row],[fecha_inicio]],Tbla_proyectos[[#This Row],[fecha_fin]],"M")) | L6: BOGOTA | M6: BOGOTÁ, D.C. | N6: =IF(Tbla_proyectos[[#This Row],[municipio]]="","",VLOOKUP(Tbla_proyectos[[#This Row],[municipio]],INDIRECT(Tbla_proyectos[[#This Row],[departamento]]),2,0)) -> 4.3161077 | O6: =IF(Tbla_proyectos[[#This Row],[municipio]]="","",VLOOKUP(Tbla_proyectos[[#This Row],[municipio]],INDIRECT(Tbla_proyectos[[#This Row],[departamento]]),2,0)) -> 4.3161077 | P6: Continuidad
A7: 2530IINDSGIO-5 | B7: =LEFT(Tbla_proyectos[[#This Row],[codigo_proyecto]],4) -> 2530 | C7: PROPUESTA DE GESTION Y ANALISIS ESTRATEGICO | D7: Prácticas | E7: Asesoría técnica por medio de reuniones de exploración, entendimiento, evaluación y ejecución de propuestas de proyectos de ingeniería que le ayuden a la entidad a mejorar la gestión de procesos. | F7: Gestión de Procesos | G7: Asesoría Técnica y Capacitación | H7: Giovanna Rosa Fiorillo Obando | K7: =IF(OR(Tbla_proyectos[[#This Row],[fecha_inicio]]="",Tbla_proyectos[[#This Row],[fecha_fin]]=""),"",DATEDIF(Tbla_proyectos[[#This Row],[fecha_inicio]],Tbla_proyectos[[#This Row],[fecha_fin]],"M")) | L7: BOGOTA | M7: BOGOTÁ, D.C. | N7: =IF(Tbla_proyectos[[#This Row],[municipio]]="","",VLOOKUP(Tbla_proyectos[[#This Row],[municipio]],INDIRECT(Tbla_proyectos[[#This Row],[departamento]]),2,0)) -> 4.3161077 | O7: =IF(Tbla_proyectos[[#This Row],[municipio]]="","",VLOOKUP(Tbla_proyectos[[#This Row],[municipio]],INDIRECT(Tbla_proyectos[[#This Row],[departamento]]),2,0)) -> 4.3161077 | P7: Continuidad
A8: 2430IINDSGIO-5 | B8: =LEFT(Tbla_proyectos[[#This Row],[codigo_proyecto]],4) -> 2430 | C8: PROPUESTA DE GESTION Y ANALISIS ESTRATEGICO | D8: Prácticas | E8: Asesoría técnica por medio de reuniones de exploración, entendimiento, evaluación y ejecución de propuestas de proyectos de ingeniería que le ayuden a la entidad a mejorar la gestión de procesos. | F8: Gestión de Procesos | G8: Asesoría Técnica y Capacitación | H8: Giovanna Rosa Fiorillo Obando | K8: =IF(OR(Tbla_proyectos[[#This Row],[fecha_inicio]]="",Tbla_proyectos[[#This Row],[fecha_fin]]=""),"",DATEDIF(Tbla_proyectos[[#This Row],[fecha_inicio]],Tbla_proyectos[[#This Row],[fecha_fin]],"M")) | L8: BOGOTA | M8: BOGOTÁ, D.C. | N8: =IF(Tbla_proyectos[[#This Row],[municipio]]="","",VLOOKUP(Tbla_proyectos[[#This Row],[municipio]],INDIRECT(Tbla_proyectos[[#This Row],[departamento]]),2,0)) -> 4.3161077 | O8: =IF(Tbla_proyectos[[#This Row],[municipio]]="","",VLOOKUP(Tbla_proyectos[[#This Row],[municipio]],INDIRECT(Tbla_proyectos[[#This Row],[departamento]]),2,0)) -> 4.3161077 | P8: Continuidad
A9: 2510IELECDIE-1 | B9: =LEFT(Tbla_proyectos[[#This Row],[codigo_proyecto]],4) -> 2510 | C9: Sistema Antiescape en dispositivos de cuidado residencial | D9: Prácticas | E9: Diseño e implentación de un sistema anti-escape para mejorar la seguridad de la entidad. Realización de actividades de integración con los residentes de la asociación, quienes tienen Trastorno Mental Severo. | F9: Tecnologías de Asistencia | G9: Asesoría Técnica | H9: Diego Fernando Parra Díaz | K9: =IF(OR(Tbla_proyectos[[#This Row],[fecha_inicio]]="",Tbla_proyectos[[#This Row],[fecha_fin]]=""),"",DATEDIF(Tbla_proyectos[[#This Row],[fecha_inicio]],Tbla_proyectos[[#This Row],[fecha_fin]],"M")) | L9: BOGOTA | M9: BOGOTÁ, D.C. | N9: =IF(Tbla_proyectos[[#This Row],[municipio]]="","",VLOOKUP(Tbla_proyectos[[#This Row],[municipio]],INDIRECT(Tbla_proyectos[[#This Row],[departamento]]),2,0)) -> 4.3161077 | O9: =IF(Tbla_proyectos[[#This Row],[municipio]]="","",VLOOKUP(Tbla_proyectos[[#This Row],[municipio]],INDIRECT(Tbla_proyectos[[#This Row],[departamento]]),2,0)) -> 4.3161077 | P9: Continuidad
A10: 2530IELECDIE-1 | B10: =LEFT(Tbla_proyectos[[#This Row],[codigo_proyecto]],4) -> 2530 | C10: Sistema Antiescape en dispositivos de cuidado residencial | D10: Prácticas | E10: Diseño e implentación de un sistema anti-escape para mejorar la seguridad de la entidad. Realización de actividades de integración con los residentes de la asociación, quienes tienen Trastorno Mental Severo. | F10: Tecnologías de Asistencia | G10: Asesoría Técnica | H10: Diego Fernando Parra Díaz | K10: =IF(OR(Tbla_proyectos[[#This Row],[fecha_inicio]]="",Tbla_proyectos[[#This Row],[fecha_fin]]=""),"",DATEDIF(Tbla_proyectos[[#This Row],[fecha_inicio]],Tbla_proyectos[[#This Row],[fecha_fin]],"M")) | L10: BOGOTA | M10: BOGOTÁ, D.C. | N10: =IF(Tbla_proyectos[[#This Row],[municipio]]="","",VLOOKUP(Tbla_proyectos[[#This Row],[municipio]],INDIRECT(Tbla_proyectos[[#This Row],[departamento]]),2,0)) -> 4.3161077 | O10: =IF(Tbla_proyectos[[#This Row],[municipio]]="","",VLOOKUP(Tbla_proyectos[[#This Row],[municipio]],INDIRECT(Tbla_proyectos[[#This Row],[departamento]]),2,0)) -> 4.3161077 | P10: Continuidad
A11: 2430IELECDIE-1 | B11: =LEFT(Tbla_proyectos[[#This Row],[codigo_proyecto]],4) -> 2430 | C11: Sistema Antiescape en dispositivos de cuidado residencial | D11: Prácticas | E11: Diseño e implentación de un sistema anti-escape para mejorar la seguridad de la entidad. Realización de actividades de integración con los residentes de la asociación, quienes tienen Trastorno Mental Severo. | F11: Tecnologías de Asistencia | G11: Asesoría Técnica | H11: Diego Fernando Parra Díaz | K11: =IF(OR(Tbla_proyectos[[#This Row],[fecha_inicio]]="",Tbla_proyectos[[#This Row],[fecha_fin]]=""),"",DATEDIF(Tbla_proyectos[[#This Row],[fecha_inicio]],Tbla_proyectos[[#This Row],[fecha_fin]],"M")) | L11: BOGOTA | M11: BOGOTÁ, D.C. | N11: =IF(Tbla_proyectos[[#This Row],[municipio]]="","",VLOOKUP(Tbla_proyectos[[#This Row],[municipio]],INDIRECT(Tbla_proyectos[[#This Row],[departamento]]),2,0)) -> 4.3161077 | O11: =IF(Tbla_proyectos[[#This Row],[municipio]]="","",VLOOKUP(Tbla_proyectos[[#This Row],[municipio]],INDIRECT(Tbla_proyectos[[#This Row],[departamento]]),2,0)) -> 4.3161077 | P11: Continuidad
A12: 2520IELECDIE-1 | B12: =LEFT(Tbla_proyectos[[#This Row],[codigo_proyecto]],4) -> 2520 | C12: Sistema Antiescape en dispositivos de cuidado residencial | D12: Prácticas | E12: Diseño e implentación de un sistema anti-escape para mejorar la seguridad de la entidad. Realización de actividades de integración con los residentes de la asociación, quienes tienen Trastorno Mental Severo. | F12: Tecnologías de Asistencia | G12: Asesoría Técnica | H12: Diego Fernando Parra Díaz | K12: =IF(OR(Tbla_proyectos[[#This Row],[fecha_inicio]]="",Tbla_proyectos[[#This Row],[fecha_fin]]=""),"",DATEDIF(Tbla_proyectos[[#This Row],[fecha_inicio]],Tbla_proyectos[[#This Row],[fecha_fin]],"M")) | L12: BOGOTA | M12: BOGOTÁ, D.C. | N12: =IF(Tbla_proyectos[[#This Row],[municipio]]="","",VLOOKUP(Tbla_proyectos[[#This Row],[municipio]],INDIRECT(Tbla_proyectos[[#This Row],[departamento]]),2,0)) -> 4.3161077 | O12: =IF(Tbla_proyectos[[#This Row],[municipio]]="","",VLOOKUP(Tbla_proyectos[[#This Row],[municipio]],INDIRECT(Tbla_proyectos[[#This Row],[departamento]]),2,0)) -> 4.3161077 | P12: Continuidad
A13: 2510IINDSBLA-4 | B13: =LEFT(Tbla_proyectos[[#This Row],[codigo_proyecto]],4) -> 2510 | C13: Asesoría en proyecto productivo en las veredas altas del Municipio de Venecia, Cundinamarca | D13: Prácticas | E13: Definición de un posible abordaje de proyecto productivo agrícola en las veredas altas del Municipio de Venencia, Cundinamarca | F13: Gestión de Procesos | G13: Asesoría Técnica | H13: Blanca Elvira Oviedo Torres | K13: =IF(OR(Tbla_proyectos[[#This Row],[fecha_inicio]]="",Tbla_proyectos[[#This Row],[fecha_fin]]=""),"",DATEDIF(Tbla_proyectos[[#This Row],[fecha_inicio]],Tbla_proyectos[[#This Row],[fecha_fin]],"M")) | L13: CUNDINAMARCA | M13: VENECIA | N13: =IF(Tbla_proyectos[[#This Row],[municipio]]="","",VLOOKUP(Tbla_proyectos[[#This Row],[municipio]],INDIRECT(Tbla_proyectos[[#This Row],[departamento]]),2,0)) -> 4.0633421 | O13: =IF(Tbla_proyectos[[#This Row],[municipio]]="","",VLOOKUP(Tbla_proyectos[[#This Row],[municipio]],INDIRECT(Tbla_proyectos[[#This Row],[departamento]]),2,0)) -> 4.0633421 | P13: Nuevo
A14: 2510ICIVLJOR-1 | B14: =LEFT(Tbla_proyectos[[#This Row],[codigo_proyecto]],4) -> 2510 | C14: Desarrollo del plan de gestión integral del recurso hídrico para la ZRC de Venecia (Cundinamarca) | D14: Prácticas | E14: Diagnóstico de la relación de la comunidad de la ZRC con el agua a nivel de unidad de vivienda. | F14: Gestión del Agua | G14: Apoyo Técnico | H14: Jorge Escobar Vargas | K14: =IF(OR(Tbla_proyectos[[#This Row],[fecha_inicio]]="",Tbla_proyectos[[#This Row],[fecha_fin]]=""),"",DATEDIF(Tbla_proyectos[[#This Row],[fecha_inicio]],Tbla_proyectos[[#This Row],[fecha_fin]],"M")) | L14: CUNDINAMARCA | M14: VENECIA | N14: =IF(Tbla_proyectos[[#This Row],[municipio]]="","",VLOOKUP(Tbla_proyectos[[#This Row],[municipio]],INDIRECT(Tbla_proyectos[[#This Row],[departamento]]),2,0)) -> 4.0633421 | O14: =IF(Tbla_proyectos[[#This Row],[municipio]]="","",VLOOKUP(Tbla_proyectos[[#This Row],[municipio]],INDIRECT(Tbla_proyectos[[#This Row],[departamento]]),2,0)) -> 4.0633421 | P14: Continuidad
A15: 2510ISISTJUA-12 | B15: =LEFT(Tbla_proyectos[[#This Row],[codigo_proyecto]],4) -> 2510 | D15: Prácticas | E15: Identificar y documentar las falencias de la organización. Realizar un análisis DOFA detallado. Sistematizar la información recopilada. Proponer estrategias de mejora basadas en el análisis realizado. Brindar asesoría técnica sobre las mejoras organizacionales. | F15: Gestión de Procesos | G15: Asesoría Técnica | H15: Juan Felipe Salcedo | K15: =IF(OR(Tbla_proyectos[[#This Row],[fecha_inicio]]="",Tbla_proyectos[[#This Row],[fecha_fin]]=""),"",DATEDIF(Tbla_proyectos[[#This Row],[fecha_inicio]],Tbla_proyectos[[#This Row],[fecha_fin]],"M")) | L15: BOGOTA | M15: BOGOTÁ, D.C. | N15: =IF(Tbla_proyectos[[#This Row],[municipio]]="","",VLOOKUP(Tbla_proyectos[[#This Row],[municipio]],INDIRECT(Tbla_proyectos[[#This Row],[departamento]]),2,0)) -> 4.3161077 | O15: =IF(Tbla_proyectos[[#This Row],[municipio]]="","",VLOOKUP(Tbla_proyectos[[#This Row],[municipio]],INDIRECT(Tbla_proyectos[[#This Row],[departamento]]),2,0)) -> 4.3161077 | P15: Nuevo
A16: 2430ICIVLLUI-1 | B16: =LEFT(Tbla_proyectos[[#This Row],[codigo_proyecto]],4) -> 2430 | C16: PROYECTO “CAPACITACIÓN EN CONSTRUCCIÓN-CAMACOL” | D16: Prácticas | E16: Capacitación en construcción a trabajadores de la industria de la construcción afiliada a CAMACOL. Módulo 1, Módulo 2, Módulo 3 o Módulo 4. | F16: Capacitación en Construcción | G16: Capacitación | H16: Luis Alberto Jaramillo Gómez | K16: =IF(OR(Tbla_proyectos[[#This Row],[fecha_inicio]]="",Tbla_proyectos[[#This Row],[fecha_fin]]=""),"",DATEDIF(Tbla_proyectos[[#This Row],[fecha_inicio]],Tbla_proyectos[[#This Row],[fecha_fin]],"M")) | L16: BOGOTA | M16: BOGOTÁ, D.C. | N16: =IF(Tbla_proyectos[[#This Row],[municipio]]="","",VLOOKUP(Tbla_proyectos[[#This Row],[municipio]],INDIRECT(Tbla_proyectos[[#This Row],[departamento]]),2,0)) -> 4.3161077 | O16: =IF(Tbla_proyectos[[#This Row],[municipio]]="","",VLOOKUP(Tbla_proyectos[[#This Row],[municipio]],INDIRECT(Tbla_proyectos[[#This Row],[departamento]]),2,0)) -> 4.3161077 | P16: Continuidad
A17: 2510ICIVLLUI-1 | B17: =LEFT(Tbla_proyectos[[#This Row],[codigo_proyecto]],4) -> 2510 | C17: PROYECTO “CAPACITACIÓN EN CONSTRUCCIÓN-CAMACOL” | D17: Prácticas | E17: Capacitación en construcción a trabajadores de la industria de la construcción afiliada a CAMACOL. Módulo 1, Módulo 2, Módulo 3 o Módulo 4. | F17: Capacitación en Construcción | G17: Capacitación | H17: Luis Alberto Jaramillo Gómez | K17: =IF(OR(Tbla_proyectos[[#This Row],[fecha_inicio]]="",Tbla_proyectos[[#This Row],[fecha_fin]]=""),"",DATEDIF(Tbla_proyectos[[#This Row],[fecha_inicio]],Tbla_proyectos[[#This Row],[fecha_fin]],"M")) | L17: BOGOTA | M17: BOGOTÁ, D.C. | N17: =IF(Tbla_proyectos[[#This Row],[municipio]]="","",VLOOKUP(Tbla_proyectos[[#This Row],[municipio]],INDIRECT(Tbla_proyectos[[#This Row],[departamento]]),2,0)) -> 4.3161077 | O17: =IF(Tbla_proyectos[[#This Row],[municipio]]="","",VLOOKUP(Tbla_proyectos[[#This Row],[municipio]],INDIRECT(Tbla_proyectos[[#This Row],[departamento]]),2,0)) -> 4.3161077 | P17: Continuidad
A18: 2530ICIVLLUI-1 | B18: =LEFT(Tbla_proyectos[[#This Row],[codigo_proyecto]],4) -> 2530 | C18: PROYECTO “CAPACITACIÓN EN CONSTRUCCIÓN-CAMACOL” | D18: Prácticas | E18: Capacitación en construcción a trabajadores de la industria de la construcción afiliada a CAMACOL. Módulo 1, Módulo 2, Módulo 3 o Módulo 4. | F18: Capacitación en Construcción | G18: Capacitación | H18: Luis Alberto Jaramillo Gómez | K18: =IF(OR(Tbla_proyectos[[#This Row],[fecha_inicio]]="",Tbla_proyectos[[#This Row],[fecha_fin]]=""),"",DATEDIF(Tbla_proyectos[[#This Row],[fecha_inicio]],Tbla_proyectos[[#This Row],[fecha_fin]],"M")) | L18: BOGOTA | M18: BOGOTÁ, D.C. | N18: =IF(Tbla_proyectos[[#This Row],[municipio]]="","",VLOOKUP(Tbla_proyectos[[#This Row],[municipio]],INDIRECT(Tbla_proyectos[[#This Row],[departamento]]),2,0)) -> 4.3161077 | O18: =IF(Tbla_proyectos[[#This Row],[municipio]]="","",VLOOKUP(Tbla_proyectos[[#This Row],[municipio]],INDIRECT(Tbla_proyectos[[#This Row],[departamento]]),2,0)) -> 4.3161077 | P18: Continuidad
A19: 2430ICIVLLUI-6 | B19: =LEFT(Tbla_proyectos[[#This Row],[codigo_proyecto]],4) -> 2430 | C19: CURSO BÁSICO EN CONSTRICCIÓN | D19: Prácticas | E19: Desarrollar cursos de capacitación a maestros de la construcción, con énfasis en el desarrollo de bases teóricas y habilidades prácticas a partir de cuatro módulos, | F19: Capacitación en Construcción | G19: Capacitación | H19: Luis Alberto Jaramillo Gómez | K19: =IF(OR(Tbla_proyectos[[#This Row],[fecha_inicio]]="",Tbla_proyectos[[#This Row],[fecha_fin]]=""),"",DATEDIF(Tbla_proyectos[[#This Row],[fecha_inicio]],Tbla_proyectos[[#This Row],[fecha_fin]],"M")) | L19: BOGOTA | M19: BOGOTÁ, D.C. | N19: =IF(Tbla_proyectos[[#This Row],[municipio]]="","",VLOOKUP(Tbla_proyectos[[#This Row],[municipio]],INDIRECT(Tbla_proyectos[[#This Row],[departamento]]),2,0)) -> 4.3161077 | O19: =IF(Tbla_proyectos[[#This Row],[municipio]]="","",VLOOKUP(Tbla_proyectos[[#This Row],[municipio]],INDIRECT(Tbla_proyectos[[#This Row],[departamento]]),2,0)) -> 4.3161077 | P19: Continuidad
A20: 2530IELECDIE-5 | B20: =LEFT(Tbla_proyectos[[#This Row],[codigo_proyecto]],4) -> 2530 | C20: Diagnodtico de necesidades de asesoría técnica para las labores de cuidado | D20: Prácticas | E20: Levantamiento de reporte de necesidades de asesoría técnica para las labores de cuidado de la institución | F20: Tecnologías de Asistencia | G20: Asesoría Técnica | H20: Diego Fernando Parra Díaz | K20: =IF(OR(Tbla_proyectos[[#This Row],[fecha_inicio]]="",Tbla_proyectos[[#This Row],[fecha_fin]]=""),"",DATEDIF(Tbla_proyectos[[#This Row],[fecha_inicio]],Tbla_proyectos[[#This Row],[fecha_fin]],"M")) | L20: BOGOTA | M20: BOGOTÁ, D.C. | N20: =IF(Tbla_proyectos[[#This Row],[municipio]]="","",VLOOKUP(Tbla_proyectos[[#This Row],[municipio]],INDIRECT(Tbla_proyectos[[#This Row],[departamento]]),2,0)) -> 4.3161077 | O20: =IF(Tbla_proyectos[[#This Row],[municipio]]="","",VLOOKUP(Tbla_proyectos[[#This Row],[municipio]],INDIRECT(Tbla_proyectos[[#This Row],[departamento]]),2,0)) -> 4.3161077 | P20: Nuevo
A21: 2510IINDSBLA-2 | B21: =LEFT(Tbla_proyectos[[#This Row],[codigo_proyecto]],4) -> 2510 | C21: Manual de Funciones para el Colegio | D21: Prácticas | E21: Completar la elaboración del manual de funciones del Colegio Gabriel García Márquez y divulgarlo para asegurar su implementación y comprensión. | F21: Gestión de Procesos | G21: Asesoría Técnica | H21: Blanca Elvira Oviedo Torres | K21: =IF(OR(Tbla_proyectos[[#This Row],[fecha_inicio]]="",Tbla_proyectos[[#This Row],[fecha_fin]]=""),"",DATEDIF(Tbla_proyectos[[#This Row],[fecha_inicio]],Tbla_proyectos[[#This Row],[fecha_fin]],"M")) | L21: BOGOTA | M21: BOGOTÁ, D.C. | N21: =IF(Tbla_proyectos[[#This Row],[municipio]]="","",VLOOKUP(Tbla_proyectos[[#This Row],[municipio]],INDIRECT(Tbla_proyectos[[#This Row],[departamento]]),2,0)) -> 4.3161077 | O21: =IF(Tbla_proyectos[[#This Row],[municipio]]="","",VLOOKUP(Tbla_proyectos[[#This Row],[municipio]],INDIRECT(Tbla_proyectos[[#This Row],[departamento]]),2,0)) -> 4.3161077 | P21: Continuidad
A22: 2430ISISTALI-2 | B22: =LEFT(Tbla_proyectos[[#This Row],[codigo_proyecto]],4) -> 2430 | C22: Proyecto 3 | D22: Prácticas | E22: Desarrollo de software utilizando técnicas de programación modernas. Aplicación del modelo RUP (Rational Unified Process) en el ciclo de vida del proyecto de software. Implementación y seguimiento de metodologías SCRUM para la gestión ágil de proyectos. | F22: Desarrollo de Software | G22: Asesoría Técnica | H22: Alicia Mercedes Arenas Valderrama | K22: =IF(OR(Tbla_proyectos[[#This Row],[fecha_inicio]]="",Tbla_proyectos[[#This Row],[fecha_fin]]=""),"",DATEDIF(Tbla_proyectos[[#This Row],[fecha_inicio]],Tbla_proyectos[[#This Row],[fecha_fin]],"M")) | L22: BOGOTA | M22: BOGOTÁ, D.C. | N22: =IF(Tbla_proyectos[[#This Row],[municipio]]="","",VLOOKUP(Tbla_proyectos[[#This Row],[municipio]],INDIRECT(Tbla_proyectos[[#This Row],[departamento]]),2,0)) -> 4.3161077 | O22: =IF(Tbla_proyectos[[#This Row],[municipio]]="","",VLOOKUP(Tbla_proyectos[[#This Row],[municipio]],INDIRECT(Tbla_proyectos[[#This Row],[departamento]]),2,0)) -> 4.3161077
A23: 2510ISISTALI-3 | B23: =LEFT(Tbla_proyectos[[#This Row],[codigo_proyecto]],4) -> 2510 | C23: Proyecto 3 | D23: Prácticas | E23: Desarrollar sesiones de capacitación en programación básica y avanzada y en ofimática. | F23: Capacitación en Programación | G23: Capacitación | H23: Alicia Mercedes Arenas Valderrama | K23: =IF(OR(Tbla_proyectos[[#This Row],[fecha_inicio]]="",Tbla_proyectos[[#This Row],[fecha_fin]]=""),"",DATEDIF(Tbla_proyectos[[#This Row],[fecha_inicio]],Tbla_proyectos[[#This Row],[fecha_fin]],"M")) | L23: BOGOTA | M23: BOGOTÁ, D.C. | N23: =IF(Tbla_proyectos[[#This Row],[municipio]]="","",VLOOKUP(Tbla_proyectos[[#This Row],[municipio]],INDIRECT(Tbla_proyectos[[#This Row],[departamento]]),2,0)) -> 4.3161077 | O23: =IF(Tbla_proyectos[[#This Row],[municipio]]="","",VLOOKUP(Tbla_proyectos[[#This Row],[municipio]],INDIRECT(Tbla_proyectos[[#This Row],[departamento]]),2,0)) -> 4.3161077
A24: 2430ISISTALI-3 | B24: =LEFT(Tbla_proyectos[[#This Row],[codigo_proyecto]],4) -> 2430 | C24: Proyecto 4 | D24: Prácticas | E24: Desarrollar sesiones de capacitación en programación básica y avanzada y en ofimática. | F24: Capacitación en Programación | G24: Capacitación | H24: Alicia Mercedes Arenas Valderrama | K24: =IF(OR(Tbla_proyectos[[#This Row],[fecha_inicio]]="",Tbla_proyectos[[#This Row],[fecha_fin]]=""),"",DATEDIF(Tbla_proyectos[[#This Row],[fecha_inicio]],Tbla_proyectos[[#This Row],[fecha_fin]],"M")) | L24: BOGOTA | M24: BOGOTÁ, D.C. | N24: =IF(Tbla_proyectos[[#This Row],[municipio]]="","",VLOOKUP(Tbla_proyectos[[#This Row],[municipio]],INDIRECT(Tbla_proyectos[[#This Row],[departamento]]),2,0)) -> 4.3161077 | O24: =IF(Tbla_proyectos[[#This Row],[municipio]]="","",VLOOKUP(Tbla_proyectos[[#This Row],[municipio]],INDIRECT(Tbla_proyectos[[#This Row],[departamento]]),2,0)) -> 4.3161077
A25: 2510IELECJOS-3 | B25: =LEFT(Tbla_proyectos[[#This Row],[codigo_proyecto]],4) -> 2510 | D25: Prácticas | E25: Desarrollo de sesiones de capacitación en electrónica básica, electricidad y alfabetización digital. | F25: Capacitación en Electricidad y Electrónica | G25: Capacitación | H25: José Ignacio Acevedo | K25: =IF(OR(Tbla_proyectos[[#This Row],[fecha_inicio]]="",Tbla_proyectos[[#This Row],[fecha_fin]]=""),"",DATEDIF(Tbla_proyectos[[#This Row],[fecha_inicio]],Tbla_proyectos[[#This Row],[fecha_fin]],"M")) | L25: BOGOTA | M25: BOGOTÁ, D.C. | N25: =IF(Tbla_proyectos[[#This Row],[municipio]]="","",VLOOKUP(Tbla_proyectos[[#This Row],[municipio]],INDIRECT(Tbla_proyectos[[#This Row],[departamento]]),2,0)) -> 4.3161077 | O25: =IF(Tbla_proyectos[[#This Row],[municipio]]="","",VLOOKUP(Tbla_proyectos[[#This Row],[municipio]],INDIRECT(Tbla_proyectos[[#This Row],[departamento]]),2,0)) -> 4.3161077 | P25: Continuidad
A26: 2430IELECJOS-3 | B26: =LEFT(Tbla_proyectos[[#This Row],[codigo_proyecto]],4) -> 2430 | C26: PROSOFI | D26: Prácticas | E26: Desarrollo de sesiones de capacitación en electrónica básica, electricidad y alfabetización digital. | F26: Capacitación en Electricidad y Electrónica | G26: Capacitación | H26: José Ignacio Acevedo Gordo | K26: =IF(OR(Tbla_proyectos[[#This Row],[fecha_inicio]]="",Tbla_proyectos[[#This Row],[fecha_fin]]=""),"",DATEDIF(Tbla_proyectos[[#This Row],[fecha_inicio]],Tbla_proyectos[[#This Row],[fecha_fin]],"M")) | L26: BOGOTA | M26: BOGOTÁ, D.C. | N26: =IF(Tbla_proyectos[[#This Row],[municipio]]="","",VLOOKUP(Tbla_proyectos[[#This Row],[municipio]],INDIRECT(Tbla_proyectos[[#This Row],[departamento]]),2,0)) -> 4.3161077 | O26: =IF(Tbla_proyectos[[#This Row],[municipio]]="","",VLOOKUP(Tbla_proyectos[[#This Row],[municipio]],INDIRECT(Tbla_proyectos[[#This Row],[departamento]]),2,0)) -> 4.3161077 | P26: Continuidad
A27: 2510IINDSBLA-1 | B27: =LEFT(Tbla_proyectos[[#This Row],[codigo_proyecto]],4) -> 2510 | C27: Estrategias para lograr equilibrio económico | D27: Prácticas | E27: Análisis de aspectos organizacionales del colegio para identificar áreas de mejora. Propuesta de acciones estratégicas para lograr el equilibrio económico del colegio. | F27: Gestión de Procesos | G27: Asesoría Técnica y Capacitación | H27: Blanca Elvira Oviedo Torres | K27: =IF(OR(Tbla_proyectos[[#This Row],[fecha_inicio]]="",Tbla_proyectos[[#This Row],[fecha_fin]]=""),"",DATEDIF(Tbla_proyectos[[#This Row],[fecha_inicio]],Tbla_proyectos[[#This Row],[fecha_fin]],"M")) | L27: BOGOTA | M27: BOGOTÁ, D.C. | N27: =IF(Tbla_proyectos[[#This Row],[municipio]]="","",VLOOKUP(Tbla_proyectos[[#This Row],[municipio]],INDIRECT(Tbla_proyectos[[#This Row],[departamento]]),2,0)) -> 4.3161077 | O27: =IF(Tbla_proyectos[[#This Row],[municipio]]="","",VLOOKUP(Tbla_proyectos[[#This Row],[municipio]],INDIRECT(Tbla_proyectos[[#This Row],[departamento]]),2,0)) -> 4.3161077 | P27: Continuidad
A28: 2430IINDSBLA-1 | B28: =LEFT(Tbla_proyectos[[#This Row],[codigo_proyecto]],4) -> 2430 | C28: Estrategias para lograr equilibrio económico | D28: Prácticas | E28: Análisis de aspectos organizacionales del colegio para identificar áreas de mejora. Propuesta de acciones estratégicas para lograr el equilibrio económico del colegio. | F28: Gestión de Procesos | G28: Asesoría Técnica y Capacitación | H28: Blanca Elvira Oviedo Torres | K28: =IF(OR(Tbla_proyectos[[#This Row],[fecha_inicio]]="",Tbla_proyectos[[#This Row],[fecha_fin]]=""),"",DATEDIF(Tbla_proyectos[[#This Row],[fecha_inicio]],Tbla_proyectos[[#This Row],[fecha_fin]],"M")) | L28: BOGOTA | M28: BOGOTÁ, D.C. | N28: =IF(Tbla_proyectos[[#This Row],[municipio]]="","",VLOOKUP(Tbla_proyectos[[#This Row],[municipio]],INDIRECT(Tbla_proyectos[[#This Row],[departamento]]),2,0)) -> 4.3161077 | O28: =IF(Tbla_proyectos[[#This Row],[municipio]]="","",VLOOKUP(Tbla_proyectos[[#This Row],[municipio]],INDIRECT(Tbla_proyectos[[#This Row],[departamento]]),2,0)) -> 4.3161077 | P28: Continuidad
A29: 2510IELECJOS-5 | B29: =LEFT(Tbla_proyectos[[#This Row],[codigo_proyecto]],4) -> 2510 | C29: Reparación de Equipos de Computo CSGH | D29: Prácticas | E29: Revisión y reparación de equipos de computo y de sistemas de sonido y audiovisuales. Capacitación en sistemas | F29: Reparación de Electrodomésticos | G29: Asesoría Técnica y Capacitación | H29: José Ignacio Acevedo | K29: =IF(OR(Tbla_proyectos[[#This Row],[fecha_inicio]]="",Tbla_proyectos[[#This Row],[fecha_fin]]=""),"",DATEDIF(Tbla_proyectos[[#This Row],[fecha_inicio]],Tbla_proyectos[[#This Row],[fecha_fin]],"M")) | L29: BOGOTA | M29: BOGOTÁ, D.C. | N29: =IF(Tbla_proyectos[[#This Row],[municipio]]="","",VLOOKUP(Tbla_proyectos[[#This Row],[municipio]],INDIRECT(Tbla_proyectos[[#This Row],[departamento]]),2,0)) -> 4.3161077 | O29: =IF(Tbla_proyectos[[#This Row],[municipio]]="","",VLOOKUP(Tbla_proyectos[[#This Row],[municipio]],INDIRECT(Tbla_proyectos[[#This Row],[departamento]]),2,0)) -> 4.3161077 | P29: Continuidad
A30: 2430IELECJOS-5 | B30: =LEFT(Tbla_proyectos[[#This Row],[codigo_proyecto]],4) -> 2430 | C30: Reparación de Equipos de Computo CSGH | D30: Prácticas | E30: Revisión y reparación de equipos de computo y de sistemas de sonido y audiovisuales. Capacitación en sistemas | F30: Reparación de Electrodomésticos | G30: Asesoría Técnica y Capacitación | H30: José Ignacio Acevedo Gordo | K30: =IF(OR(Tbla_proyectos[[#This Row],[fecha_inicio]]="",Tbla_proyectos[[#This Row],[fecha_fin]]=""),"",DATEDIF(Tbla_proyectos[[#This Row],[fecha_inicio]],Tbla_proyectos[[#This Row],[fecha_fin]],"M")) | L30: BOGOTA | M30: BOGOTÁ, D.C. | N30: =IF(Tbla_proyectos[[#This Row],[municipio]]="","",VLOOKUP(Tbla_proyectos[[#This Row],[municipio]],INDIRECT(Tbla_proyectos[[#This Row],[departamento]]),2,0)) -> 4.3161077 | O30: =IF(Tbla_proyectos[[#This Row],[municipio]]="","",VLOOKUP(Tbla_proyectos[[#This Row],[municipio]],INDIRECT(Tbla_proyectos[[#This Row],[departamento]]),2,0)) -> 4.3161077 | P30: Continuidad
A31: 2510ICIVLLUI-4 | B31: =LEFT(Tbla_proyectos[[#This Row],[codigo_proyecto]],4) -> 2510 | C31: PROYECTO "ALTOS DE LA FLORIDA – SOACHA" | D31: Prácticas | E31: Elaboración de la topografía del sector 3 de Altos de la Florida en Soacha como base para la proyección de las redes de acueducto y alcantarillado. Realización de estudios de estabilidad estructural en casas del barrio Altos de la Florida en la Comuna 6 del municipio de Soacha, Cundinamarca. Definición preliminar de las redes de acueducto y alcantarillado sanitario para el sector 3 de Altos de la Florida en Soacha. | F31: Acueductos Comunitarios | G31: Asesoría Técnica | H31: Luis Alberto Jaramillo Gómez | K31: =IF(OR(Tbla_proyectos[[#This Row],[fecha_inicio]]="",Tbla_proyectos[[#This Row],[fecha_fin]]=""),"",DATEDIF(Tbla_proyectos[[#This Row],[fecha_inicio]],Tbla_proyectos[[#This Row],[fecha_fin]],"M")) | L31: CUNDINAMARCA | M31: SOACHA | N31: =IF(Tbla_proyectos[[#This Row],[municipio]]="","",VLOOKUP(Tbla_proyectos[[#This Row],[municipio]],INDIRECT(Tbla_proyectos[[#This Row],[departamento]]),2,0)) -> 4.5818663 | O31: =IF(Tbla_proyectos[[#This Row],[municipio]]="","",VLOOKUP(Tbla_proyectos[[#This Row],[municipio]],INDIRECT(Tbla_proyectos[[#This Row],[departamento]]),2,0)) -> 4.5818663 | P31: Continuidad
A32: 2430ICIVLLUI-4 | B32: =LEFT(Tbla_proyectos[[#This Row],[codigo_proyecto]],4) -> 2430 | C32: PROYECTO "ALTOS DE LA FLORIDA – SOACHA" | D32: Prácticas | E32: Elaboración de la topografía del sector 3 de Altos de la Florida en Soacha como base para la proyección de las redes de acueducto y alcantarillado. Realización de estudios de estabilidad estructural en casas del barrio Altos de la Florida en la Comuna 6 del municipio de Soacha, Cundinamarca. Definición preliminar de las redes de acueducto y alcantarillado sanitario para el sector 3 de Altos de la Florida en Soacha. | F32: Gestión del Riesgo | G32: Asesoría Técnica | H32: Luis Alberto Jaramillo Gómez | K32: =IF(OR(Tbla_proyectos[[#This Row],[fecha_inicio]]="",Tbla_proyectos[[#This Row],[fecha_fin]]=""),"",DATEDIF(Tbla_proyectos[[#This Row],[fecha_inicio]],Tbla_proyectos[[#This Row],[fecha_fin]],"M")) | L32: CUNDINAMARCA | M32: SOACHA | N32: =IF(Tbla_proyectos[[#This Row],[municipio]]="","",VLOOKUP(Tbla_proyectos[[#This Row],[municipio]],INDIRECT(Tbla_proyectos[[#This Row],[departamento]]),2,0)) -> 4.5818663 | O32: =IF(Tbla_proyectos[[#This Row],[municipio]]="","",VLOOKUP(Tbla_proyectos[[#This Row],[municipio]],INDIRECT(Tbla_proyectos[[#This Row],[departamento]]),2,0)) -> 4.5818663 | P32: Continuidad
A33: 2430ISISTALI-27 | B33: =LEFT(Tbla_proyectos[[#This Row],[codigo_proyecto]],4) -> 2430 | D33: Prácticas | E33: Desarrollo y ejecución de sesiones de capacitación en alfabetización digital. Capacitación con énfasis en herramientas de ofimática. | F33: Capacitación en Ofimática | H33: Alicia Mercedes Arenas Valderrama | K33: =IF(OR(Tbla_proyectos[[#This Row],[fecha_inicio]]="",Tbla_proyectos[[#This Row],[fecha_fin]]=""),"",DATEDIF(Tbla_proyectos[[#This Row],[fecha_inicio]],Tbla_proyectos[[#This Row],[fecha_fin]],"M")) | L33: CUNDINAMARCA | M33: SOACHA | N33: =IF(Tbla_proyectos[[#This Row],[municipio]]="","",VLOOKUP(Tbla_proyectos[[#This Row],[municipio]],INDIRECT(Tbla_proyectos[[#This Row],[departamento]]),2,0)) -> 4.5818663 | O33: =IF(Tbla_proyectos[[#This Row],[municipio]]="","",VLOOKUP(Tbla_proyectos[[#This Row],[municipio]],INDIRECT(Tbla_proyectos[[#This Row],[departamento]]),2,0)) -> 4.5818663
A34: 2510IINDSCLA-5 | B34: =LEFT(Tbla_proyectos[[#This Row],[codigo_proyecto]],4) -> 2510 | D34: Prácticas | E34: Asesoría técnica por medio de reuniones de exploración, entendimiento, evaluación y ejecución de propuestas de proyectos de ingeniería que le ayuden a la entidad a mejorar la gestión de procesos. | F34: Gestión de Procesos | G34: Asesoría Técnica y Capacitación | H34: Clara Mabel Solano Vanegas | K34: =IF(OR(Tbla_proyectos[[#This Row],[fecha_inicio]]="",Tbla_proyectos[[#This Row],[fecha_fin]]=""),"",DATEDIF(Tbla_proyectos[[#This Row],[fecha_inicio]],Tbla_proyectos[[#This Row],[fecha_fin]],"M")) | L34: BOGOTA | M34: BOGOTÁ, D.C. | N34: =IF(Tbla_proyectos[[#This Row],[municipio]]="","",VLOOKUP(Tbla_proyectos[[#This Row],[municipio]],INDIRECT(Tbla_proyectos[[#This Row],[departamento]]),2,0)) -> 4.3161077 | O34: =IF(Tbla_proyectos[[#This Row],[municipio]]="","",VLOOKUP(Tbla_proyectos[[#This Row],[municipio]],INDIRECT(Tbla_proyectos[[#This Row],[departamento]]),2,0)) -> 4.3161077 | P34: Continuidad
A35: 2530IINDSCLA-5 | B35: =LEFT(Tbla_proyectos[[#This Row],[codigo_proyecto]],4) -> 2530 | C35: Mejoramiento procesos alistamiento prendas. | D35: Prácticas | E35: Asesoría técnica por medio de reuniones de exploración, entendimiento, evaluación y ejecución de propuestas de proyectos de ingeniería que le ayuden a la entidad a mejorar la gestión de procesos. | F35: Gestión de Procesos | G35: Asesoría Técnica y Capacitación | H35: Clara Mabel Solano Vanegas | K35: =IF(OR(Tbla_proyectos[[#This Row],[fecha_inicio]]="",Tbla_proyectos[[#This Row],[fecha_fin]]=""),"",DATEDIF(Tbla_proyectos[[#This Row],[fecha_inicio]],Tbla_proyectos[[#This Row],[fecha_fin]],"M")) | L35: BOGOTA | M35: BOGOTÁ, D.C. | N35: =IF(Tbla_proyectos[[#This Row],[municipio]]="","",VLOOKUP(Tbla_proyectos[[#This Row],[municipio]],INDIRECT(Tbla_proyectos[[#This Row],[departamento]]),2,0)) -> 4.3161077 | O35: =IF(Tbla_proyectos[[#This Row],[municipio]]="","",VLOOKUP(Tbla_proyectos[[#This Row],[municipio]],INDIRECT(Tbla_proyectos[[#This Row],[departamento]]),2,0)) -> 4.3161077 | P35: Continuidad
A36: 2430IINDSCLA-5 | B36: =LEFT(Tbla_proyectos[[#This Row],[codigo_proyecto]],4) -> 2430 | D36: Prácticas | E36: Asesoría técnica por medio de reuniones de exploración, entendimiento, evaluación y ejecución de propuestas de proyectos de ingeniería que le ayuden a la entidad a mejorar la gestión de procesos. | F36: Gestión de Procesos | G36: Asesoría Técnica y Capacitación | H36: Clara Mabel Solano Vanegas | K36: =IF(OR(Tbla_proyectos[[#This Row],[fecha_inicio]]="",Tbla_proyectos[[#This Row],[fecha_fin]]=""),"",DATEDIF(Tbla_proyectos[[#This Row],[fecha_inicio]],Tbla_proyectos[[#This Row],[fecha_fin]],"M")) | L36: BOGOTA | M36: BOGOTÁ, D.C. | N36: =IF(Tbla_proyectos[[#This Row],[municipio]]="","",VLOOKUP(Tbla_proyectos[[#This Row],[municipio]],INDIRECT(Tbla_proyectos[[#This Row],[departamento]]),2,0)) -> 4.3161077 | O36: =IF(Tbla_proyectos[[#This Row],[municipio]]="","",VLOOKUP(Tbla_proyectos[[#This Row],[municipio]],INDIRECT(Tbla_proyectos[[#This Row],[departamento]]),2,0)) -> 4.3161077 | P36: Continuidad
A37: 2510BIOINMAR-7 | B37: =LEFT(Tbla_proyectos[[#This Row],[codigo_proyecto]],4) -> 2510 | C37: Proyecto de bioseguridad, información, protocolos y procedimientos | D37: Prácticas | E37: Elaborar, documentar y propopner protocolos de bioseguridad y construcción de procesos y procedimientos | F37: Gestión de Procesos | G37: Asesoría Técnica | H37: Marcela Camargo Pabón | K37: =IF(OR(Tbla_proyectos[[#This Row],[fecha_inicio]]="",Tbla_proyectos[[#This Row],[fecha_fin]]=""),"",DATEDIF(Tbla_proyectos[[#This Row],[fecha_inicio]],Tbla_proyectos[[#This Row],[fecha_fin]],"M")) | L37: BOGOTA | M37: BOGOTÁ, D.C. | N37: =IF(Tbla_proyectos[[#This Row],[municipio]]="","",VLOOKUP(Tbla_proyectos[[#This Row],[municipio]],INDIRECT(Tbla_proyectos[[#This Row],[departamento]]),2,0)) -> 4.3161077 | O37: =IF(Tbla_proyectos[[#This Row],[municipio]]="","",VLOOKUP(Tbla_proyectos[[#This Row],[municipio]],INDIRECT(Tbla_proyectos[[#This Row],[departamento]]),2,0)) -> 4.3161077 | P37: Nuevo
A38: 2510ISISTALI-4 | B38: =LEFT(Tbla_proyectos[[#This Row],[codigo_proyecto]],4) -> 2510 | C38: Proyecto 4 | D38: Prácticas | E38: Desarrollo y mantenimiento de página web. Capacitación en desarrollo web. | F38: Desarrollo Web | G38: Asesoría Técnica y Capacitación | H38: Alicia Mercedes Arenas Valderrama | K38: =IF(OR(Tbla_proyectos[[#This Row],[fecha_inicio]]="",Tbla_proyectos[[#This Row],[fecha_fin]]=""),"",DATEDIF(Tbla_proyectos[[#This Row],[fecha_inicio]],Tbla_proyectos[[#This Row],[fecha_fin]],"M")) | L38: BOGOTA | M38: BOGOTÁ, D.C. | N38: =IF(Tbla_proyectos[[#This Row],[municipio]]="","",VLOOKUP(Tbla_proyectos[[#This Row],[municipio]],INDIRECT(Tbla_proyectos[[#This Row],[departamento]]),2,0)) -> 4.3161077 | O38: =IF(Tbla_proyectos[[#This Row],[municipio]]="","",VLOOKUP(Tbla_proyectos[[#This Row],[municipio]],INDIRECT(Tbla_proyectos[[#This Row],[departamento]]),2,0)) -> 4.3161077
